Workbook

Sheet Dashboard
B2: GL-Agent | Publication simulator v1.0
B3: How much control should an AI agent carry, and where do you stop? This workbook computes the turning points.
B4: Synthetic scenarios • 7 September 2026 • no empirical calibration
B6: Editable input | C6: the dial | D6: calculated automatically | E6: key results
B8: INPUTS • annual units • blue cells are editable
B9: Attack campaigns per year (lambda) | C9: 40 | H9: Fatigue | I9: =1/(1+EXP(MIN(700,MAX(-700,($C$17*$C$24-$C$18)/$C$19)))) -> 0.66075637
B10: Baseline success prob. per campaign (q0) | C10: 0.2 | H10: Detection | I10: =$C$15*(1-EXP(-$C$16*$C$24)) -> 0.50569645
B11: Loss per successful campaign (L0) | C11: 50000 | H11: h | I11: =I9*I10 -> 0.33414215
B12: Defence productivity γ (per unit x) | C12: 0.35 | H12: h derivative | I12: =$C$15*($C$16*EXP(-$C$16*$C$24)*I9-(1-EXP(-$C$16*$C$24))*$C$17/$C$19*I9*(1-I9)) -> -0.053909321
B13: Cash-cost slope c (currency/year per x) | C13: 20000 | H13: Risk derivative | I13: =$C$27*EXP(-$C$12*$C$24)*(-$C$12*(1-I11)-I12)+2*$C$20*$C$24 -> -3583.5008
B14: Utility-tax slope τ (currency/year per x) | C14: 30000 | H14: Welfare derivative | I14: =-I13-$C$28 -> -46416.499
B15: Max review effectiveness (h_max) | C15: 0.8 | H15: Input validity | I15: =IF(AND(C9>=0,C10>=0,C10<=1,C11>=0,C12>=0,C13>=0,C14>=0,C13+C14>0,C15>=0,C15<=1,C16>=0,C17>=0,C18>=0,C19>0,C20>=0,C21>=0,C24>=0,C24<=10),"VALID","CHECK INPUTS") -> VALID
B16: Detection responsiveness κ_d (per unit x) | C16: 0.5 | H16: Deploy vs outside option | I16: =IF(I15<>"VALID","Check inputs",IF(C39>C40,"Deployment worthwhile","Outside option preferred")) -> Deployment worthwhile
B17: Alert-load slope v₀ (alerts/year per x) | C17: 800
B18: Review capacity A_c (alerts/year) | C18: 2000
B19: Fatigue smoothness s (alerts/year) | C19: 600
B20: Displacement coefficient d (currency/year per x²) | C20: 8000
B21: Baseline delivered benefit B₀ (currency/year) | C21: 1500000
B23: THE DIAL
B24: Control intensity x (0–10) | C24: 2
B26: RESULTS (calculated automatically - nothing to change below)
B27: Baseline attack loss R₀ | C27: =C9*C10*C11 -> 400000
B28: All-in slope k = c + τ | C28: =C13+C14 -> 50000
B29: q-only solution | C29: =IF(C12*C27>C28,"Interior","Corner: no q-only investment") -> Interior
B30: q-only optimal intensity | C30: =IF(AND(C12>0,C28>0,C12*C27>C28),LN(C12*C27/C28)/C12,0) -> 2.9417698
B31: q-only optimized residual risk | C31: =C27*EXP(-C12*C30) -> 142857.14
B32: Full-model welfare optimum (0.01 grid) | C32: =INDEX(Curves!A2:A1002,MATCH(MAX(Curves!M2:M1002),Curves!M2:M1002,0)) -> 1.45
B33: Full-model global risk minimum (0.01 grid) | C33: =INDEX(Curves!A2:A1002,MATCH(MIN(Curves!I2:I1002),Curves!I2:I1002,0)) -> 2.06
B34: Attack loss at welfare optimum | C34: =INDEX(Curves!G2:G1002,MATCH(C32,Curves!A2:A1002,0)) -> 161110.93
B35: Displacement at welfare optimum | C35: =C20*C32^2 -> 16820
B36: q-only all-in burden / R₀ | C36: =IF(C27>0,C28*C30/C27,0) -> 0.36772122
B37: Conditional 1/e check | C37: =IF(C36<=1/EXP(1)+0.000000001,"PASS (restricted q-only model)","CHECK") -> PASS (restricted q-only model)
B38: Full-model burden / R₀ (not bounded by 1/e) | C38: =IF(C27>0,C28*C32/C27,0) -> 0.18125
B39: Maximum welfare on grid | C39: =MAX(Curves!M2:M1002) -> 1249569.1
B40: Outside option (non-deployment) | C40: =0 -> 0
B41: Search-range diagnostic | C41: =IF(OR(C32>=10,C33>=10),"Upper edge: extend grid",IF(C32=0,"Welfare corner at zero","Interior grid optima")) -> Interior grid optima
B42: Welfare at selected x | C42: =C21-C28*C24-C27*EXP(-C12*C24)*(1-I11)-C20*C24^2 -> 1235737.9
B43: Total risk at selected x | C43: =C27*EXP(-C12*C24)*(1-I11)+C20*C24^2 -> 164262.09
B44: Marginal welfare at selected x | C44: =IF(I14>0.000001,"Increasing",IF(I14< -0.000001,"Decreasing","Stationary")) -> Decreasing
B45: Marginal risk at selected x | C45: =IF(I13>0.000001,"Increasing",IF(I13< -0.000001,"Decreasing","Stationary")) -> Decreasing
...

Sheet Curves
A1: Intensity x | B1: q(x) | C1: Alerts / year | D1: Detection ceiling | E1: Fatigue factor | F1: Prevented fraction h | G1: Attack loss / year | H1: Displacement increment | I1: Total risk / year | J1: Cash cost / year | K1: Utility tax / year | L1: Delivered benefit | M1: Welfare / year | N1: All-in burden | O1: h derivative | P1: Risk derivative | Q1: Welfare derivative
A2: =(2-2)/100 -> 0 | B2: =Dashboard!$C$10*EXP(-Dashboard!$C$12*A2) -> 0.2 | C2: =Dashboard!$C$17*A2 -> 0 | D2: =Dashboard!$C$15*(1-EXP(-Dashboard!$C$16*A2)) -> 0 | E2: =1/(1+EXP(MIN(700,MAX(-700,(C2-Dashboard!$C$18)/Dashboard!$C$19)))) -> 0.9655548 | F2: =D2*E2 -> 0 | G2: =Dashboard!$C$9*B2*Dashboard!$C$11*(1-F2) -> 400000 | H2: =Dashboard!$C$20*A2^2 -> 0 | I2: =G2+H2 -> 400000 | J2: =Dashboard!$C$13*A2 -> 0 | K2: =Dashboard!$C$14*A2 -> 0 | L2: =Dashboard!$C$21-K2 -> 1500000 | M2: =L2-I2-J2 -> 1100000 | N2: =J2+K2 -> 0 | O2: =Dashboard!$C$15*(Dashboard!$C$16*EXP(-Dashboard!$C$16*A2)*E2-(1-EXP(-Dashboard!$C$16*A2))*Dashboard!$C$17/Dashboard!$C$19*E2*(1-E2)) -> 0.38622192 | P2: =Dashboard!$C$9*B2*Dashboard!$C$11*(-Dashboard!$C$12*(1-F2)-O2)+2*Dashboard!$C$20*A2 -> -294488.77 | Q2: =-P2-Dashboard!$C$13-Dashboard!$C$14 -> 244488.77
A3: =(3-2)/100 -> 0.01 | B3: =Dashboard!$C$10*EXP(-Dashboard!$C$12*A3) -> 0.19930122 | C3: =Dashboard!$C$17*A3 -> 8 | D3: =Dashboard!$C$15*(1-EXP(-Dashboard!$C$16*A3)) -> 0.0039900166 | E3: =1/(1+EXP(MIN(700,MAX(-700,(C3-Dashboard!$C$18)/Dashboard!$C$19)))) -> 0.96510859 | F3: =D3*E3 -> 0.0038507993 | G3: =Dashboard!$C$9*B3*Dashboard!$C$11*(1-F3) -> 397067.51 | H3: =Dashboard!$C$20*A3^2 -> 0.8 | I3: =G3+H3 -> 397068.31 | J3: =Dashboard!$C$13*A3 -> 200 | K3: =Dashboard!$C$14*A3 -> 300 | L3: =Dashboard!$C$21-K3 -> 1499700 | M3: =L3-I3-J3 -> 1102431.7 | N3: =J3+K3 -> 500 | O3: =Dashboard!$C$15*(Dashboard!$C$16*EXP(-Dashboard!$C$16*A3)*E3-(1-EXP(-Dashboard!$C$16*A3))*Dashboard!$C$17/Dashboard!$C$19*E3*(1-E3)) -> 0.38393889 | P3: =Dashboard!$C$9*B3*Dashboard!$C$11*(-Dashboard!$C$12*(1-F3)-O3)+2*Dashboard!$C$20*A3 -> -291852.61 | Q3: =-P3-Dashboard!$C$13-Dashboard!$C$14 -> 241852.61
A4: =(4-2)/100 -> 0.02 | B4: =Dashboard!$C$10*EXP(-Dashboard!$C$12*A4) -> 0.19860489 | C4: =Dashboard!$C$17*A4 -> 16 | D4: =Dashboard!$C$15*(1-EXP(-Dashboard!$C$16*A4)) -> 0.007960133 | E4: =1/(1+EXP(MIN(700,MAX(-700,(C4-Dashboard!$C$18)/Dashboard!$C$19)))) -> 0.96465681 | F4: =D4*E4 -> 0.0076787965 | G4: =Dashboard!$C$9*B4*Dashboard!$C$11*(1-F4) -> 394159.68 | H4: =Dashboard!$C$20*A4^2 -> 3.2 | I4: =G4+H4 -> 394162.88 | J4: =Dashboard!$C$13*A4 -> 400 | K4: =Dashboard!$C$14*A4 -> 600 | L4: =Dashboard!$C$21-K4 -> 1499400 | M4: =L4-I4-J4 -> 1104837.1 | N4: =J4+K4 -> 1000 | O4: =Dashboard!$C$15*(Dashboard!$C$16*EXP(-Dashboard!$C$16*A4)*E4-(1-EXP(-Dashboard!$C$16*A4))*Dashboard!$C$17/Dashboard!$C$19*E4*(1-E4)) -> 0.38166147 | P4: =Dashboard!$C$9*B4*Dashboard!$C$11*(-Dashboard!$C$12*(1-F4)-O4)+2*Dashboard!$C$20*A4 -> -289235.56 | Q4: =-P4-Dashboard!$C$13-Dashboard!$C$14 -> 239235.56
A5: =(5-2)/100 -> 0.03 | B5: =Dashboard!$C$10*EXP(-Dashboard!$C$12*A5) -> 0.19791099 | C5: =Dashboard!$C$17*A5 -> 24 | D5: =Dashboard!$C$15*(1-EXP(-Dashboard!$C$16*A5)) -> 0.011910448 | E5: =1/(1+EXP(MIN(700,MAX(-700,(C5-Dashboard!$C$18)/Dashboard!$C$19)))) -> 0.9641994 | F5: =D5*E5 -> 0.011484047 | G5: =Dashboard!$C$9*B5*Dashboard!$C$11*(1-F5) -> 391276.33 | H5: =Dashboard!$C$20*A5^2 -> 7.2 | I5: =G5+H5 -> 391283.53 | J5: =Dashboard!$C$13*A5 -> 600 | K5: =Dashboard!$C$14*A5 -> 900 | L5: =Dashboard!$C$21-K5 -> 1499100 | M5: =L5-I5-J5 -> 1107216.5 | N5: =J5+K5 -> 1500 | O5: =Dashboard!$C$15*(Dashboard!$C$16*EXP(-Dashboard!$C$16*A5)*E5-(1-EXP(-Dashboard!$C$16*A5))*Dashboard!$C$17/Dashboard!$C$19*E5*(1-E5)) -> 0.37938955 | P5: =Dashboard!$C$9*B5*Dashboard!$C$11*(-Dashboard!$C$12*(1-F5)-O5)+2*Dashboard!$C$20*A5 -> -286637.44 | Q5: =-P5-Dashboard!$C$13-Dashboard!$C$14 -> 236637.44
A6: =(6-2)/100 -> 0.04 | B6: =Dashboard!$C$10*EXP(-Dashboard!$C$12*A6) -> 0.19721951 | C6: =Dashboard!$C$17*A6 -> 32 | D6: =Dashboard!$C$15*(1-EXP(-Dashboard!$C$16*A6)) -> 0.015841061 | E6: =1/(1+EXP(MIN(700,MAX(-700,(C6-Dashboard!$C$18)/Dashboard!$C$19)))) -> 0.96373628 | F6: =D6*E6 -> 0.015266606 | G6: =Dashboard!$C$9*B6*Dashboard!$C$11*(1-F6) -> 388417.27 | H6: =Dashboard!$C$20*A6^2 -> 12.8 | I6: =G6+H6 -> 388430.07 | J6: =Dashboard!$C$13*A6 -> 800 | K6: =Dashboard!$C$14*A6 -> 1200 | L6: =Dashboard!$C$21-K6 -> 1498800 | M6: =L6-I6-J6 -> 1109569.9 | N6: =J6+K6 -> 2000 | O6: =Dashboard!$C$15*(Dashboard!$C$16*EXP(-Dashboard!$C$16*A6)*E6-(1-EXP(-Dashboard!$C$16*A6))*Dashboard!$C$17/Dashboard!$C$19*E6*(1-E6)) -> 0.37712305 | P6: =Dashboard!$C$9*B6*Dashboard!$C$11*(-Dashboard!$C$12*(1-F6)-O6)+2*Dashboard!$C$20*A6 -> -284058.09 | Q6: =-P6-Dashboard!$C$13-Dashboard!$C$14 -> 234058.09
A7: =(7-2)/100 -> 0.05 | B7: =Dashboard!$C$10*EXP(-Dashboard!$C$12*A7) -> 0.19653045 | C7: =Dashboard!$C$17*A7 -> 40 | D7: =Dashboard!$C$15*(1-EXP(-Dashboard!$C$16*A7)) -> 0.01975207 | E7: =1/(1+EXP(MIN(700,MAX(-700,(C7-Dashboard!$C$18)/Dashboard!$C$19)))) -> 0.96326741 | F7: =D7*E7 -> 0.019026526 | G7: =Dashboard!$C$9*B7*Dashboard!$C$11*(1-F7) -> 385582.31 | H7: =Dashboard!$C$20*A7^2 -> 20 | I7: =G7+H7 -> 385602.31 | J7: =Dashboard!$C$13*A7 -> 1000 | K7: =Dashboard!$C$14*A7 -> 1500 | L7: =Dashboard!$C$21-K7 -> 1498500 | M7: =L7-I7-J7 -> 1111897.7 | N7: =J7+K7 -> 2500 | O7: =Dashboard!$C$15*(Dashboard!$C$16*EXP(-Dashboard!$C$16*A7)*E7-(1-EXP(-Dashboard!$C$16*A7))*Dashboard!$C$17/Dashboard!$C$19*E7*(1-E7)) -> 0.37486184 | P7: =Dashboard!$C$9*B7*Dashboard!$C$11*(-Dashboard!$C$12*(1-F7)-O7)+2*Dashboard!$C$20*A7 -> -281497.34 | Q7: =-P7-Dashboard!$C$13-Dashboard!$C$14 -> 231497.34
A8: =(8-2)/100 -> 0.06 | B8: =Dashboard!$C$10*EXP(-Dashboard!$C$12*A8) -> 0.19584379 | C8: =Dashboard!$C$17*A8 -> 48 | D8: =Dashboard!$C$15*(1-EXP(-Dashboard!$C$16*A8)) -> 0.023643573 | E8: =1/(1+EXP(MIN(700,MAX(-700,(C8-Dashboard!$C$18)/Dashboard!$C$19)))) -> 0.96279271 | F8: =D8*E8 -> 0.02276386 | G8: =Dashboard!$C$9*B8*Dashboard!$C$11*(1-F8) -> 382771.26 | H8: =Dashboard!$C$20*A8^2 -> 28.8 | I8: =G8+H8 -> 382800.06 | J8: =Dashboard!$C$13*A8 -> 1200 | K8: =Dashboard!$C$14*A8 -> 1800 | L8: =Dashboard!$C$21-K8 -> 1498200 | M8: =L8-I8-J8 -> 1114199.9 | N8: =J8+K8 -> 3000 | O8: =Dashboard!$C$15*(Dashboard!$C$16*EXP(-Dashboard!$C$16*A8)*E8-(1-EXP(-Dashboard!$C$16*A8))*Dashboard!$C$17/Dashboard!$C$19*E8*(1-E8)) -> 0.37260584 | P8: =Dashboard!$C$9*B8*Dashboard!$C$11*(-Dashboard!$C$12*(1-F8)-O8)+2*Dashboard!$C$20*A8 -> -278955.03 | Q8: =-P8-Dashboard!$C$13-Dashboard!$C$14 -> 228955.03
A9: =(9-2)/100 -> 0.07 | B9: =Dashboard!$C$10*EXP(-Dashboard!$C$12*A9) -> 0.19515954 | C9: =Dashboard!$C$17*A9 -> 56 | D9: =Dashboard!$C$15*(1-EXP(-Dashboard!$C$16*A9)) -> 0.027515667 | E9: =1/(1+EXP(MIN(700,MAX(-700,(C9-Dashboard!$C$18)/Dashboard!$C$19)))) -> 0.96231211 | F9: =D9*E9 -> 0.02647866 | G9: =Dashboard!$C$9*B9*Dashboard!$C$11*(1-F9) -> 379983.95 | H9: =Dashboard!$C$20*A9^2 -> 39.2 | I9: =G9+H9 -> 380023.15 | J9: =Dashboard!$C$13*A9 -> 1400 | K9: =Dashboard!$C$14*A9 -> 2100 | L9: =Dashboard!$C$21-K9 -> 1497900 | M9: =L9-I9-J9 -> 1116476.9 | N9: =J9+K9 -> 3500 | O9: =Dashboard!$C$15*(Dashboard!$C$16*EXP(-Dashboard!$C$16*A9)*E9-(1-EXP(-Dashboard!$C$16*A9))*Dashboard!$C$17/Dashboard!$C$19*E9*(1-E9)) -> 0.37035495 | P9: =Dashboard!$C$9*B9*Dashboard!$C$11*(-Dashboard!$C$12*(1-F9)-O9)+2*Dashboard!$C$20*A9 -> -276430.98 | Q9: =-P9-Dashboard!$C$13-Dashboard!$C$14 -> 226430.98
A10: =(10-2)/100 -> 0.08 | B10: =Dashboard!$C$10*EXP(-Dashboard!$C$12*A10) -> 0.19447767 | C10: =Dashboard!$C$17*A10 -> 64 | D10: =Dashboard!$C$15*(1-EXP(-Dashboard!$C$16*A10)) -> 0.031368449 | E10: =1/(1+EXP(MIN(700,MAX(-700,(C10-Dashboard!$C$18)/Dashboard!$C$19)))) -> 0.96182555 | F10: =D10*E10 -> 0.030170975 | G10: =Dashboard!$C$9*B10*Dashboard!$C$11*(1-F10) -> 377220.18 | H10: =Dashboard!$C$20*A10^2 -> 51.2 | I10: =G10+H10 -> 377271.38 | J10: =Dashboard!$C$13*A10 -> 1600 | K10: =Dashboard!$C$14*A10 -> 2400 | L10: =Dashboard!$C$21-K10 -> 1497600 | M10: =L10-I10-J10 -> 1118728.6 | N10: =J10+K10 -> 4000 | O10: =Dashboard!$C$15*(Dashboard!$C$16*EXP(-Dashboard!$C$16*A10)*E10-(1-EXP(-Dashboard!$C$16*A10))*Dashboard!$C$17/Dashboard!$C$19*E10*(1-E10)) -> 0.36810905 | P10: =Dashboard!$C$9*B10*Dashboard!$C$11*(-Dashboard!$C$12*(1-F10)-O10)+2*Dashboard!$C$20*A10 -> -273925.05 | Q10: =-P10-Dashboard!$C$13-Dashboard!$C$14 -> 223925.05
A11: =(11-2)/100 -> 0.09 | B11: =Dashboard!$C$10*EXP(-Dashboard!$C$12*A11) -> 0.19379819 | C11: =Dashboard!$C$17*A11 -> 72 | D11: =Dashboard!$C$15*(1-EXP(-Dashboard!$C$16*A11)) -> 0.035202015 | E11: =1/(1+EXP(MIN(700,MAX(-700,(C11-Dashboard!$C$18)/Dashboard!$C$19)))) -> 0.96133296 | F11: =D11*E11 -> 0.033840857 | G11: =Dashboard!$C$9*B11*Dashboard!$C$11*(1-F11) -> 374479.79 | H11: =Dashboard!$C$20*A11^2 -> 64.8 | I11: =G11+H11 -> 374544.59 | J11: =Dashboard!$C$13*A11 -> 1800 | K11: =Dashboard!$C$14*A11 -> 2700 | L11: =Dashboard!$C$21-K11 -> 1497300 | M11: =L11-I11-J11 -> 1120955.4 | N11: =J11+K11 -> 4500 | O11: =Dashboard!$C$15*(Dashboard!$C$16*EXP(-Dashboard!$C$16*A11)*E11-(1-EXP(-Dashboard!$C$16*A11))*Dashboard!$C$17/Dashboard!$C$19*E11*(1-E11)) -> 0.36586806 | P11: =Dashboard!$C$9*B11*Dashboard!$C$11*(-Dashboard!$C$12*(1-F11)-O11)+2*Dashboard!$C$20*A11 -> -271437.06 | Q11: =-P11-Dashboard!$C$13-Dashboard!$C$14 -> 221437.06
A12: =(12-2)/100 -> 0.1 | B12: =Dashboard!$C$10*EXP(-Dashboard!$C$12*A12) -> 0.19312108 | C12: =Dashboard!$C$17*A12 -> 80 | D12: =Dashboard!$C$15*(1-EXP(-Dashboard!$C$16*A12)) -> 0.03901646 | E12: =1/(1+EXP(MIN(700,MAX(-700,(C12-Dashboard!$C$18)/Dashboard!$C$19)))) -> 0.96083428 | F12: =D12*E12 -> 0.037488353 | G12: =Dashboard!$C$9*B12*Dashboard!$C$11*(1-F12) -> 371762.58 | H12: =Dashboard!$C$20*A12^2 -> 80 | I12: =G12+H12 -> 371842.58 | J12: =Dashboard!$C$13*A12 -> 2000 | K12: =Dashboard!$C$14*A12 -> 3000 | L12: =Dashboard!$C$21-K12 -> 1497000 | M12: =L12-I12-J12 -> 1123157.4 | N12: =J12+K12 -> 5000 | O12: =Dashboard!$C$15*(Dashboard!$C$16*EXP(-Dashboard!$C$16*A12)*E12-(1-EXP(-Dashboard!$C$16*A12))*Dashboard!$C$17/Dashboard!$C$19*E12*(1-E12)) -> 0.36363186 | P12: =Dashboard!$C$9*B12*Dashboard!$C$11*(-Dashboard!$C$12*(1-F12)-O12)+2*Dashboard!$C$20*A12 -> -268966.86 | Q12: =-P12-Dashboard!$C$13-Dashboard!$C$14 -> 218966.86
A13: =(13-2)/100 -> 0.11 | B13: =Dashboard!$C$10*EXP(-Dashboard!$C$12*A13) -> 0.19244634 | C13: =Dashboard!$C$17*A13 -> 88 | D13: =Dashboard!$C$15*(1-EXP(-Dashboard!$C$16*A13)) -> 0.042811882 | E13: =1/(1+EXP(MIN(700,MAX(-700,(C13-Dashboard!$C$18)/Dashboard!$C$19)))) -> 0.96032943 | F13: =D13*E13 -> 0.04111351 | G13: =Dashboard!$C$9*B13*Dashboard!$C$11*(1-F13) -> 369068.39 | H13: =Dashboard!$C$20*A13^2 -> 96.8 | I13: =G13+H13 -> 369165.19 | J13: =Dashboard!$C$13*A13 -> 2200 | K13: =Dashboard!$C$14*A13 -> 3300 | L13: =Dashboard!$C$21-K13 -> 1496700 | M13: =L13-I13-J13 -> 1125334.8 | N13: =J13+K13 -> 5500 | O13: =Dashboard!$C$15*(Dashboard!$C$16*EXP(-Dashboard!$C$16*A13)*E13-(1-EXP(-Dashboard!$C$16*A13))*Dashboard!$C$17/Dashboard!$C$19*E13*(1-E13)) -> 0.36140035 | P13: =Dashboard!$C$9*B13*Dashboard!$C$11*(-Dashboard!$C$12*(1-F13)-O13)+2*Dashboard!$C$20*A13 -> -266514.29 | Q13: =-P13-Dashboard!$C$13-Dashboard!$C$14 -> 216514.29
A14: =(14-2)/100 -> 0.12 | B14: =Dashboard!$C$10*EXP(-Dashboard!$C$12*A14) -> 0.19177396 | C14: =Dashboard!$C$17*A14 -> 96 | D14: =Dashboard!$C$15*(1-EXP(-Dashboard!$C$16*A14)) -> 0.046588373 | E14: =1/(1+EXP(MIN(700,MAX(-700,(C14-Dashboard!$C$18)/Dashboard!$C$19)))) -> 0.95981834 | F14: =D14*E14 -> 0.044716375 | G14: =Dashboard!$C$9*B14*Dashboard!$C$11*(1-F14) -> 366397.04 | H14: =Dashboard!$C$20*A14^2 -> 115.2 | I14: =G14+H14 -> 366512.24 | J14: =Dashboard!$C$13*A14 -> 2400 | K14: =Dashboard!$C$14*A14 -> 3600 | L14: =Dashboard!$C$21-K14 -> 1496400 | M14: =L14-I14-J14 -> 1127487.8 | N14: =J14+K14 -> 6000 | O14: =Dashboard!$C$15*(Dashboard!$C$16*EXP(-Dashboard!$C$16*A14)*E14-(1-EXP(-Dashboard!$C$16*A14))*Dashboard!$C$17/Dashboard!$C$19*E14*(1-E14)) -> 0.35917344 | P14: =Dashboard!$C$9*B14*Dashboard!$C$11*(-Dashboard!$C$12*(1-F14)-O14)+2*Dashboard!$C$20*A14 -> -264079.19 | Q14: =-P14-Dashboard!$C$13-Dashboard!$C$14 -> 214079.19
A15: =(15-2)/100 -> 0.13 | B15: =Dashboard!$C$10*EXP(-Dashboard!$C$12*A15) -> 0.19110392 | C15: =Dashboard!$C$17*A15 -> 104 | D15: =Dashboard!$C$15*(1-EXP(-Dashboard!$C$16*A15)) -> 0.050346029 | E15: =1/(1+EXP(MIN(700,MAX(-700,(C15-Dashboard!$C$18)/Dashboard!$C$19)))) -> 0.95930095 | F15: =D15*E15 -> 0.048296994 | G15: =Dashboard!$C$9*B15*Dashboard!$C$11*(1-F15) -> 363748.35 | H15: =Dashboard!$C$20*A15^2 -> 135.2 | I15: =G15+H15 -> 363883.55 | J15: =Dashboard!$C$13*A15 -> 2600 | K15: =Dashboard!$C$14*A15 -> 3900 | L15: =Dashboard!$C$21-K15 -> 1496100 | M15: =L15-I15-J15 -> 1129616.4 | N15: =J15+K15 -> 6500 | O15: =Dashboard!$C$15*(Dashboard!$C$16*EXP(-Dashboard!$C$16*A15)*E15-(1-EXP(-Dashboard!$C$16*A15))*Dashboard!$C$17/Dashboard!$C$19*E15*(1-E15)) -> 0.35695103 | P15: =Dashboard!$C$9*B15*Dashboard!$C$11*(-Dashboard!$C$12*(1-F15)-O15)+2*Dashboard!$C$20*A15 -> -261661.4 | Q15: =-P15-Dashboard!$C$13-Dashboard!$C$14 -> 211661.4
A16: =(16-2)/100 -> 0.14 | B16: =Dashboard!$C$10*EXP(-Dashboard!$C$12*A16) -> 0.19043623 | C16: =Dashboard!$C$17*A16 -> 112 | D16: =Dashboard!$C$15*(1-EXP(-Dashboard!$C$16*A16)) -> 0.054084944 | E16: =1/(1+EXP(MIN(700,MAX(-700,(C16-Dashboard!$C$18)/Dashboard!$C$19)))) -> 0.95877718 | F16: =D16*E16 -> 0.05185541 | G16: =Dashboard!$C$9*B16*Dashboard!$C$11*(1-F16) -> 361122.15 | H16: =Dashboard!$C$20*A16^2 -> 156.8 | I16: =G16+H16 -> 361278.95 | J16: =Dashboard!$C$13*A16 -> 2800 | K16: =Dashboard!$C$14*A16 -> 4200 | L16: =Dashboard!$C$21-K16 -> 1495800 | M16: =L16-I16-J16 -> 1131721 | N16: =J16+K16 -> 7000 | O16: =Dashboard!$C$15*(Dashboard!$C$16*EXP(-Dashboard!$C$16*A16)*E16-(1-EXP(-Dashboard!$C$16*A16))*Dashboard!$C$17/Dashboard!$C$19*E16*(1-E16)) -> 0.354733 | P16: =Dashboard!$C$9*B16*Dashboard!$C$11*(-Dashboard!$C$12*(1-F16)-O16)+2*Dashboard!$C$20*A16 -> -259260.78 | Q16: =-P16-Dashboard!$C$13-Dashboard!$C$14 -> 209260.78
A17: =(17-2)/100 -> 0.15 | B17: =Dashboard!$C$10*EXP(-Dashboard!$C$12*A17) -> 0.18977086 | C17: =Dashboard!$C$17*A17 -> 120 | D17: =Dashboard!$C$15*(1-EXP(-Dashboard!$C$16*A17)) -> 0.057805211 | E17: =1/(1+EXP(MIN(700,MAX(-700,(C17-Dashboard!$C$18)/Dashboard!$C$19)))) -> 0.95824696 | F17: =D17*E17 -> 0.055391668 | G17: =Dashboard!$C$9*B17*Dashboard!$C$11*(1-F17) -> 358518.28 | H17: =Dashboard!$C$20*A17^2 -> 180 | I17: =G17+H17 -> 358698.28 | J17: =Dashboard!$C$13*A17 -> 3000 | K17: =Dashboard!$C$14*A17 -> 4500 | L17: =Dashboard!$C$21-K17 -> 1495500 | M17: =L17-I17-J17 -> 1133801.7 | N17: =J17+K17 -> 7500 | O17: =Dashboard!$C$15*(Dashboard!$C$16*EXP(-Dashboard!$C$16*A17)*E17-(1-EXP(-Dashboard!$C$16*A17))*Dashboard!$C$17/Dashboard!$C$19*E17*(1-E17)) -> 0.35251926 | P17: =Dashboard!$C$9*B17*Dashboard!$C$11*(-Dashboard!$C$12*(1-F17)-O17)+2*Dashboard!$C$20*A17 -> -256877.17 | Q17: =-P17-Dashboard!$C$13-Dashboard!$C$14 -> 206877.17
A18: =(18-2)/100 -> 0.16 | B18: =Dashboard!$C$10*EXP(-Dashboard!$C$12*A18) -> 0.18910783 | C18: =Dashboard!$C$17*A18 -> 128 | D18: =Dashboard!$C$15*(1-EXP(-Dashboard!$C$16*A18)) -> 0.061506923 | E18: =1/(1+EXP(MIN(700,MAX(-700,(C18-Dashboard!$C$18)/Dashboard!$C$19)))) -> 0.95771023 | F18: =D18*E18 -> 0.058905809 | G18: =Dashboard!$C$9*B18*Dashboard!$C$11*(1-F18) -> 355936.56 | H18: =Dashboard!$C$20*A18^2 -> 204.8 | I18: =G18+H18 -> 356141.36 | J18: =Dashboard!$C$13*A18 -> 3200 | K18: =Dashboard!$C$14*A18 -> 4800 | L18: =Dashboard!$C$21-K18 -> 1495200 | M18: =L18-I18-J18 -> 1135858.6 | N18: =J18+K18 -> 8000 | O18: =Dashboard!$C$15*(Dashboard!$C$16*EXP(-Dashboard!$C$16*A18)*E18-(1-EXP(-Dashboard!$C$16*A18))*Dashboard!$C$17/Dashboard!$C$19*E18*(1-E18)) -> 0.3503097 | P18: =Dashboard!$C$9*B18*Dashboard!$C$11*(-Dashboard!$C$12*(1-F18)-O18)+2*Dashboard!$C$20*A18 -> -254510.41 | Q18: =-P18-Dashboard!$C$13-Dashboard!$C$14 -> 204510.41
A19: =(19-2)/100 -> 0.17 | B19: =Dashboard!$C$10*EXP(-Dashboard!$C$12*A19) -> 0.18844711 | C19: =Dashboard!$C$17*A19 -> 136 | D19: =Dashboard!$C$15*(1-EXP(-Dashboard!$C$16*A19)) -> 0.065190172 | E19: =1/(1+EXP(MIN(700,MAX(-700,(C19-Dashboard!$C$18)/Dashboard!$C$19)))) -> 0.9571669 | F19: =D19*E19 -> 0.062397875 | G19: =Dashboard!$C$9*B19*Dashboard!$C$11*(1-F19) -> 353376.82 | H19: =Dashboard!$C$20*A19^2 -> 231.2 | I19: =G19+H19 -> 353608.02 | J19: =Dashboard!$C$13*A19 -> 3400 | K19: =Dashboard!$C$14*A19 -> 5100 | L19: =Dashboard!$C$21-K19 -> 1494900 | M19: =L19-I19-J19 -> 1137892 | N19: =J19+K19 -> 8500 | O19: =Dashboard!$C$15*(Dashboard!$C$16*EXP(-Dashboard!$C$16*A19)*E19-(1-EXP(-Dashboard!$C$16*A19))*Dashboard!$C$17/Dashboard!$C$19*E19*(1-E19)) -> 0.34810423 | P19: =Dashboard!$C$9*B19*Dashboard!$C$11*(-Dashboard!$C$12*(1-F19)-O19)+2*Dashboard!$C$20*A19 -> -252160.36 | Q19: =-P19-Dashboard!$C$13-Dashboard!$C$14 -> 202160.36
A20: =(20-2)/100 -> 0.18 | B20: =Dashboard!$C$10*EXP(-Dashboard!$C$12*A20) -> 0.18778869 | C20: =Dashboard!$C$17*A20 -> 144 | D20: =Dashboard!$C$15*(1-EXP(-Dashboard!$C$16*A20)) -> 0.068855052 | E20: =1/(1+EXP(MIN(700,MAX(-700,(C20-Dashboard!$C$18)/Dashboard!$C$19)))) -> 0.95661691 | F20: =D20*E20 -> 0.065867907 | G20: =Dashboard!$C$9*B20*Dashboard!$C$11*(1-F20) -> 350838.89 | H20: =Dashboard!$C$20*A20^2 -> 259.2 | I20: =G20+H20 -> 351098.09 | J20: =Dashboard!$C$13*A20 -> 3600 | K20: =Dashboard!$C$14*A20 -> 5400 | L20: =Dashboard!$C$21-K20 -> 1494600 | M20: =L20-I20-J20 -> 1139901.9 | N20: =J20+K20 -> 9000 | O20: =Dashboard!$C$15*(Dashboard!$C$16*EXP(-Dashboard!$C$16*A20)*E20-(1-EXP(-Dashboard!$C$16*A20))*Dashboard!$C$17/Dashboard!$C$19*E20*(1-E20)) -> 0.34590274 | P20: =Dashboard!$C$9*B20*Dashboard!$C$11*(-Dashboard!$C$12*(1-F20)-O20)+2*Dashboard!$C$20*A20 -> -249826.86 | Q20: =-P20-Dashboard!$C$13-Dashboard!$C$14 -> 199826.86
A21: =(21-2)/100 -> 0.19 | B21: =Dashboard!$C$10*EXP(-Dashboard!$C$12*A21) -> 0.18713258 | C21: =Dashboard!$C$17*A21 -> 152 | D21: =Dashboard!$C$15*(1-EXP(-Dashboard!$C$16*A21)) -> 0.072501652 | E21: =1/(1+EXP(MIN(700,MAX(-700,(C21-Dashboard!$C$18)/Dashboard!$C$19)))) -> 0.95606018 | F21: =D21*E21 -> 0.069315943 | G21: =Dashboard!$C$9*B21*Dashboard!$C$11*(1-F21) -> 348322.62 | H21: =Dashboard!$C$20*A21^2 -> 288.8 | I21: =G21+H21 -> 348611.42 | J21: =Dashboard!$C$13*A21 -> 3800 | K21: =Dashboard!$C$14*A21 -> 5700 | L21: =Dashboard!$C$21-K21 -> 1494300 | M21: =L21-I21-J21 -> 1141888.6 | N21: =J21+K21 -> 9500 | O21: =Dashboard!$C$15*(Dashboard!$C$16*EXP(-Dashboard!$C$16*A21)*E21-(1-EXP(-Dashboard!$C$16*A21))*Dashboard!$C$17/Dashboard!$C$19*E21*(1-E21)) -> 0.34370513 | P21: =Dashboard!$C$9*B21*Dashboard!$C$11*(-Dashboard!$C$12*(1-F21)-O21)+2*Dashboard!$C$20*A21 -> -247509.78 | Q21: =-P21-Dashboard!$C$13-Dashboard!$C$14 -> 197509.78
A22: =(22-2)/100 -> 0.2 | B22: =Dashboard!$C$10*EXP(-Dashboard!$C$12*A22) -> 0.18647876 | C22: =Dashboard!$C$17*A22 -> 160 | D22: =Dashboard!$C$15*(1-EXP(-Dashboard!$C$16*A22)) -> 0.076130066 | E22: =1/(1+EXP(MIN(700,MAX(-700,(C22-Dashboard!$C$18)/Dashboard!$C$19)))) -> 0.95549664 | F22: =D22*E22 -> 0.072742022 | G22: =Dashboard!$C$9*B22*Dashboard!$C$11*(1-F22) -> 345827.84 | H22: =Dashboard!$C$20*A22^2 -> 320 | I22: =G22+H22 -> 346147.84 | J22: =Dashboard!$C$13*A22 -> 4000 | K22: =Dashboard!$C$14*A22 -> 6000 | L22: =Dashboard!$C$21-K22 -> 1494000 | M22: =L22-I22-J22 -> 1143852.2 | N22: =J22+K22 -> 10000 | O22: =Dashboard!$C$15*(Dashboard!$C$16*EXP(-Dashboard!$C$16*A22)*E22-(1-EXP(-Dashboard!$C$16*A22))*Dashboard!$C$17/Dashboard!$C$19*E22*(1-E22)) -> 0.34151129 | P22: =Dashboard!$C$9*B22*Dashboard!$C$11*(-Dashboard!$C$12*(1-F22)-O22)+2*Dashboard!$C$20*A22 -> -245208.95 | Q22: =-P22-Dashboard!$C$13-Dashboard!$C$14 -> 195208.95
A23: =(23-2)/100 -> 0.21 | B23: =Dashboard!$C$10*EXP(-Dashboard!$C$12*A23) -> 0.18582723 | C23: =Dashboard!$C$17*A23 -> 168 | D23: =Dashboard!$C$15*(1-EXP(-Dashboard!$C$16*A23)) -> 0.079740382 | E23: =1/(1+EXP(MIN(700,MAX(-700,(C23-Dashboard!$C$18)/Dashboard!$C$19)))) -> 0.95492622 | F23: =D23*E23 -> 0.076146181 | G23: =Dashboard!$C$9*B23*Dashboard!$C$11*(1-F23) -> 343354.39 | H23: =Dashboard!$C$20*A23^2 -> 352.8 | I23: =G23+H23 -> 343707.19 | J23: =Dashboard!$C$13*A23 -> 4200 | K23: =Dashboard!$C$14*A23 -> 6300 | L23: =Dashboard!$C$21-K23 -> 1493700 | M23: =L23-I23-J23 -> 1145792.8 | N23: =J23+K23 -> 10500 | O23: =Dashboard!$C$15*(Dashboard!$C$16*EXP(-Dashboard!$C$16*A23)*E23-(1-EXP(-Dashboard!$C$16*A23))*Dashboard!$C$17/Dashboard!$C$19*E23*(1-E23)) -> 0.33932113 | P23: =Dashboard!$C$9*B23*Dashboard!$C$11*(-Dashboard!$C$12*(1-F23)-O23)+2*Dashboard!$C$20*A23 -> -242924.25 | Q23: =-P23-Dashboard!$C$13-Dashboard!$C$14 -> 192924.25
A24: =(24-2)/100 -> 0.22 | B24: =Dashboard!$C$10*EXP(-Dashboard!$C$12*A24) -> 0.18517797 | C24: =Dashboard!$C$17*A24 -> 176 | D24: =Dashboard!$C$15*(1-EXP(-Dashboard!$C$16*A24)) -> 0.083332692 | E24: =1/(1+EXP(MIN(700,MAX(-700,(C24-Dashboard!$C$18)/Dashboard!$C$19)))) -> 0.95434883 | F24: =D24*E24 -> 0.079528457 | G24: =Dashboard!$C$9*B24*Dashboard!$C$11*(1-F24) -> 340902.1 | H24: =Dashboard!$C$20*A24^2 -> 387.2 | I24: =G24+H24 -> 341289.3 | J24: =Dashboard!$C$13*A24 -> 4400 | K24: =Dashboard!$C$14*A24 -> 6600 | L24: =Dashboard!$C$21-K24 -> 1493400 | M24: =L24-I24-J24 -> 1147710.7 | N24: =J24+K24 -> 11000 | O24: =Dashboard!$C$15*(Dashboard!$C$16*EXP(-Dashboard!$C$16*A24)*E24-(1-EXP(-Dashboard!$C$16*A24))*Dashboard!$C$17/Dashboard!$C$19*E24*(1-E24)) -> 0.33713455 | P24: =Dashboard!$C$9*B24*Dashboard!$C$11*(-Dashboard!$C$12*(1-F24)-O24)+2*Dashboard!$C$20*A24 -> -240655.52 | Q24: =-P24-Dashboard!$C$13-Dashboard!$C$14 -> 190655.52
A25: =(25-2)/100 -> 0.23 | B25: =Dashboard!$C$10*EXP(-Dashboard!$C$12*A25) -> 0.18453098 | C25: =Dashboard!$C$17*A25 -> 184 | D25: =Dashboard!$C$15*(1-EXP(-Dashboard!$C$16*A25)) -> 0.086907085 | E25: =1/(1+EXP(MIN(700,MAX(-700,(C25-Dashboard!$C$18)/Dashboard!$C$19)))) -> 0.9537644 | F25: =D25*E25 -> 0.082888884 | G25: =Dashboard!$C$9*B25*Dashboard!$C$11*(1-F25) -> 338470.83 | H25: =Dashboard!$C$20*A25^2 -> 423.2 | I25: =G25+H25 -> 338894.03 | J25: =Dashboard!$C$13*A25 -> 4600 | K25: =Dashboard!$C$14*A25 -> 6900 | L25: =Dashboard!$C$21-K25 -> 1493100 | M25: =L25-I25-J25 -> 1149606 | N25: =J25+K25 -> 11500 | O25: =Dashboard!$C$15*(Dashboard!$C$16*EXP(-Dashboard!$C$16*A25)*E25-(1-EXP(-Dashboard!$C$16*A25))*Dashboard!$C$17/Dashboard!$C$19*E25*(1-E25)) -> 0.33495143 | P25: =Dashboard!$C$9*B25*Dashboard!$C$11*(-Dashboard!$C$12*(1-F25)-O25)+2*Dashboard!$C$20*A25 -> -238402.62 | Q25: =-P25-Dashboard!$C$13-Dashboard!$C$14 -> 188402.62
A26: =(26-2)/100 -> 0.24 | B26: =Dashboard!$C$10*EXP(-Dashboard!$C$12*A26) -> 0.18388625 | C26: =Dashboard!$C$17*A26 -> 192 | D26: =Dashboard!$C$15*(1-EXP(-Dashboard!$C$16*A26)) -> 0.090463651 | E26: =1/(1+EXP(MIN(700,MAX(-700,(C26-Dashboard!$C$18)/Dashboard!$C$19)))) -> 0.95317286 | F26: =D26*E26 -> 0.086227497 | G26: =Dashboard!$C$9*B26*Dashboard!$C$11*(1-F26) -> 336060.4 | H26: =Dashboard!$C$20*A26^2 -> 460.8 | I26: =G26+H26 -> 336521.2 | J26: =Dashboard!$C$13*A26 -> 4800 | K26: =Dashboard!$C$14*A26 -> 7200 | L26: =Dashboard!$C$21-K26 -> 1492800 | M26: =L26-I26-J26 -> 1151478.8 | N26: =J26+K26 -> 12000 | O26: =Dashboard!$C$15*(Dashboard!$C$16*EXP(-Dashboard!$C$16*A26)*E26-(1-EXP(-Dashboard!$C$16*A26))*Dashboard!$C$17/Dashboard!$C$19*E26*(1-E26)) -> 0.33277168 | P26: =Dashboard!$C$9*B26*Dashboard!$C$11*(-Dashboard!$C$12*(1-F26)-O26)+2*Dashboard!$C$20*A26 -> -236165.41 | Q26: =-P26-Dashboard!$C$13-Dashboard!$C$14 -> 186165.41
A27: =(27-2)/100 -> 0.25 | B27: =Dashboard!$C$10*EXP(-Dashboard!$C$12*A27) -> 0.18324377 | C27: =Dashboard!$C$17*A27 -> 200 | D27: =Dashboard!$C$15*(1-EXP(-Dashboard!$C$16*A27)) -> 0.094002478 | E27: =1/(1+EXP(MIN(700,MAX(-700,(C27-Dashboard!$C$18)/Dashboard!$C$19)))) -> 0.95257413 | F27: =D27*E27 -> 0.089544328 | G27: =Dashboard!$C$9*B27*Dashboard!$C$11*(1-F27) -> 333670.67 | H27: =Dashboard!$C$20*A27^2 -> 500 | I27: =G27+H27 -> 334170.67 | J27: =Dashboard!$C$13*A27 -> 5000 | K27: =Dashboard!$C$14*A27 -> 7500 | L27: =Dashboard!$C$21-K27 -> 1492500 | M27: =L27-I27-J27 -> 1153329.3 | N27: =J27+K27 -> 12500 | O27: =Dashboard!$C$15*(Dashboard!$C$16*EXP(-Dashboard!$C$16*A27)*E27-(1-EXP(-Dashboard!$C$16*A27))*Dashboard!$C$17/Dashboard!$C$19*E27*(1-E27)) -> 0.3305952 | P27: =Dashboard!$C$9*B27*Dashboard!$C$11*(-Dashboard!$C$12*(1-F27)-O27)+2*Dashboard!$C$20*A27 -> -233943.76 | Q27: =-P27-Dashboard!$C$13-Dashboard!$C$14 -> 183943.76
A28: =(28-2)/100 -> 0.26 | B28: =Dashboard!$C$10*EXP(-Dashboard!$C$12*A28) -> 0.18260354 | C28: =Dashboard!$C$17*A28 -> 208 | D28: =Dashboard!$C$15*(1-EXP(-Dashboard!$C$16*A28)) -> 0.097523655 | E28: =1/(1+EXP(MIN(700,MAX(-700,(C28-Dashboard!$C$18)/Dashboard!$C$19)))) -> 0.95196812 | F28: =D28*E28 -> 0.092839411 | G28: =Dashboard!$C$9*B28*Dashboard!$C$11*(1-F28) -> 331301.47 | H28: =Dashboard!$C$20*A28^2 -> 540.8 | I28: =G28+H28 -> 331842.27 | J28: =Dashboard!$C$13*A28 -> 5200 | K28: =Dashboard!$C$14*A28 -> 7800 | L28: =Dashboard!$C$21-K28 -> 1492200 | M28: =L28-I28-J28 -> 1155157.7 | N28: =J28+K28 -> 13000 | O28: =Dashboard!$C$15*(Dashboard!$C$16*EXP(-Dashboard!$C$16*A28)*E28-(1-EXP(-Dashboard!$C$16*A28))*Dashboard!$C$17/Dashboard!$C$19*E28*(1-E28)) -> 0.32842188 | P28: =Dashboard!$C$9*B28*Dashboard!$C$11*(-Dashboard!$C$12*(1-F28)-O28)+2*Dashboard!$C$20*A28 -> -231737.51 | Q28: =-P28-Dashboard!$C$13-Dashboard!$C$14 -> 181737.51
A29: =(29-2)/100 -> 0.27 | B29: =Dashboard!$C$10*EXP(-Dashboard!$C$12*A29) -> 0.18196555 | C29: =Dashboard!$C$17*A29 -> 216 | D29: =Dashboard!$C$15*(1-EXP(-Dashboard!$C$16*A29)) -> 0.10102727 | E29: =1/(1+EXP(MIN(700,MAX(-700,(C29-Dashboard!$C$18)/Dashboard!$C$19)))) -> 0.95135477 | F29: =D29*E29 -> 0.096112776 | G29: =Dashboard!$C$9*B29*Dashboard!$C$11*(1-F29) -> 328952.67 | H29: =Dashboard!$C$20*A29^2 -> 583.2 | I29: =G29+H29 -> 329535.87 | J29: =Dashboard!$C$13*A29 -> 5400 | K29: =Dashboard!$C$14*A29 -> 8100 | L29: =Dashboard!$C$21-K29 -> 1491900 | M29: =L29-I29-J29 -> 1156964.1 | N29: =J29+K29 -> 13500 | O29: =Dashboard!$C$15*(Dashboard!$C$16*EXP(-Dashboard!$C$16*A29)*E29-(1-EXP(-Dashboard!$C$16*A29))*Dashboard!$C$17/Dashboard!$C$19*E29*(1-E29)) -> 0.32625162 | P29: =Dashboard!$C$9*B29*Dashboard!$C$11*(-Dashboard!$C$12*(1-F29)-O29)+2*Dashboard!$C$20*A29 -> -229546.54 | Q29: =-P29-Dashboard!$C$13-Dashboard!$C$14 -> 179546.54
A30: =(30-2)/100 -> 0.28 | B30: =Dashboard!$C$10*EXP(-Dashboard!$C$12*A30) -> 0.18132978 | C30: =Dashboard!$C$17*A30 -> 224 | D30: =Dashboard!$C$15*(1-EXP(-Dashboard!$C$16*A30)) -> 0.10451341 | E30: =1/(1+EXP(MIN(700,MAX(-700,(C30-Dashboard!$C$18)/Dashboard!$C$19)))) -> 0.95073399 | F30: =D30*E30 -> 0.099364453 | G30: =Dashboard!$C$9*B30*Dashboard!$C$11*(1-F30) -> 326624.09 | H30: =Dashboard!$C$20*A30^2 -> 627.2 | I30: =G30+H30 -> 327251.29 | J30: =Dashboard!$C$13*A30 -> 5600 | K30: =Dashboard!$C$14*A30 -> 8400 | L30: =Dashboard!$C$21-K30 -> 1491600 | M30: =L30-I30-J30 -> 1158748.7 | N30: =J30+K30 -> 14000 | O30: =Dashboard!$C$15*(Dashboard!$C$16*EXP(-Dashboard!$C$16*A30)*E30-(1-EXP(-Dashboard!$C$16*A30))*Dashboard!$C$17/Dashboard!$C$19*E30*(1-E30)) -> 0.32408432 | P30: =Dashboard!$C$9*B30*Dashboard!$C$11*(-Dashboard!$C$12*(1-F30)-O30)+2*Dashboard!$C$20*A30 -> -227370.71 | Q30: =-P30-Dashboard!$C$13-Dashboard!$C$14 -> 177370.71
A31: =(31-2)/100 -> 0.29 | B31: =Dashboard!$C$10*EXP(-Dashboard!$C$12*A31) -> 0.18069624 | C31: =Dashboard!$C$17*A31 -> 232 | D31: =Dashboard!$C$15*(1-EXP(-Dashboard!$C$16*A31)) -> 0.10798217 | E31: =1/(1+EXP(MIN(700,MAX(-700,(C31-Dashboard!$C$18)/Dashboard!$C$19)))) -> 0.95010571 | F31: =D31*E31 -> 0.10259447 | G31: =Dashboard!$C$9*B31*Dashboard!$C$11*(1-F31) -> 324315.6 | H31: =Dashboard!$C$20*A31^2 -> 672.8 | I31: =G31+H31 -> 324988.4 | J31: =Dashboard!$C$13*A31 -> 5800 | K31: =Dashboard!$C$14*A31 -> 8700 | L31: =Dashboard!$C$21-K31 -> 1491300 | M31: =L31-I31-J31 -> 1160511.6 | N31: =J31+K31 -> 14500 | O31: =Dashboard!$C$15*(Dashboard!$C$16*EXP(-Dashboard!$C$16*A31)*E31-(1-EXP(-Dashboard!$C$16*A31))*Dashboard!$C$17/Dashboard!$C$19*E31*(1-E31)) -> 0.32191988 | P31: =Dashboard!$C$9*B31*Dashboard!$C$11*(-Dashboard!$C$12*(1-F31)-O31)+2*Dashboard!$C$20*A31 -> -225209.88 | Q31: =-P31-Dashboard!$C$13-Dashboard!$C$14 -> 175209.88
A32: =(32-2)/100 -> 0.3 | B32: =Dashboard!$C$10*EXP(-Dashboard!$C$12*A32) -> 0.1800649 | C32: =Dashboard!$C$17*A32 -> 240 | D32: =Dashboard!$C$15*(1-EXP(-Dashboard!$C$16*A32)) -> 0.11143362 | E32: =1/(1+EXP(MIN(700,MAX(-700,(C32-Dashboard!$C$18)/Dashboard!$C$19)))) -> 0.94946984 | F32: =D32*E32 -> 0.10580286 | G32: =Dashboard!$C$9*B32*Dashboard!$C$11*(1-F32) -> 322027.05 | H32: =Dashboard!$C$20*A32^2 -> 720 | I32: =G32+H32 -> 322747.05 | J32: =Dashboard!$C$13*A32 -> 6000 | K32: =Dashboard!$C$14*A32 -> 9000 | L32: =Dashboard!$C$21-K32 -> 1491000 | M32: =L32-I32-J32 -> 1162253 | N32: =J32+K32 -> 15000 | O32: =Dashboard!$C$15*(Dashboard!$C$16*EXP(-Dashboard!$C$16*A32)*E32-(1-EXP(-Dashboard!$C$16*A32))*Dashboard!$C$17/Dashboard!$C$19*E32*(1-E32)) -> 0.31975819 | P32: =Dashboard!$C$9*B32*Dashboard!$C$11*(-Dashboard!$C$12*(1-F32)-O32)+2*Dashboard!$C$20*A32 -> -223063.92 | Q32: =-P32-Dashboard!$C$13-Dashboard!$C$14 -> 173063.92
A33: =(33-2)/100 -> 0.31 | B33: =Dashboard!$C$10*EXP(-Dashboard!$C$12*A33) -> 0.17943578 | C33: =Dashboard!$C$17*A33 -> 248 | D33: =Dashboard!$C$15*(1-EXP(-Dashboard!$C$16*A33)) -> 0.11486786 | E33: =1/(1+EXP(MIN(700,MAX(-700,(C33-Dashboard!$C$18)/Dashboard!$C$19)))) -> 0.9488263 | F33: =D33*E33 -> 0.10898964 | G33: =Dashboard!$C$9*B33*Dashboard!$C$11*(1-F33) -> 319758.27 | H33: =Dashboard!$C$20*A33^2 -> 768.8 | I33: =G33+H33 -> 320527.07 | J33: =Dashboard!$C$13*A33 -> 6200 | K33: =Dashboard!$C$14*A33 -> 9300 | L33: =Dashboard!$C$21-K33 -> 1490700 | M33: =L33-I33-J33 -> 1163972.9 | N33: =J33+K33 -> 15500 | O33: =Dashboard!$C$15*(Dashboard!$C$16*EXP(-Dashboard!$C$16*A33)*E33-(1-EXP(-Dashboard!$C$16*A33))*Dashboard!$C$17/Dashboard!$C$19*E33*(1-E33)) -> 0.31759916 | P33: =Dashboard!$C$9*B33*Dashboard!$C$11*(-Dashboard!$C$12*(1-F33)-O33)+2*Dashboard!$C$20*A33 -> -220932.7 | Q33: =-P33-Dashboard!$C$13-Dashboard!$C$14 -> 170932.7
A34: =(34-2)/100 -> 0.32 | B34: =Dashboard!$C$10*EXP(-Dashboard!$C$12*A34) -> 0.17880885 | C34: =Dashboard!$C$17*A34 -> 256 | D34: =Dashboard!$C$15*(1-EXP(-Dashboard!$C$16*A34)) -> 0.11828497 | E34: =1/(1+EXP(MIN(700,MAX(-700,(C34-Dashboard!$C$18)/Dashboard!$C$19)))) -> 0.94817501 | F34: =D34*E34 -> 0.11215485 | G34: =Dashboard!$C$9*B34*Dashboard!$C$11*(1-F34) -> 317509.14 | H34: =Dashboard!$C$20*A34^2 -> 819.2 | I34: =G34+H34 -> 318328.34 | J34: =Dashboard!$C$13*A34 -> 6400 | K34: =Dashboard!$C$14*A34 -> 9600 | L34: =Dashboard!$C$21-K34 -> 1490400 | M34: =L34-I34-J34 -> 1165671.7 | N34: =J34+K34 -> 16000 | O34: =Dashboard!$C$15*(Dashboard!$C$16*EXP(-Dashboard!$C$16*A34)*E34-(1-EXP(-Dashboard!$C$16*A34))*Dashboard!$C$17/Dashboard!$C$19*E34*(1-E34)) -> 0.31544268 | P34: =Dashboard!$C$9*B34*Dashboard!$C$11*(-Dashboard!$C$12*(1-F34)-O34)+2*Dashboard!$C$20*A34 -> -218816.09 | Q34: =-P34-Dashboard!$C$13-Dashboard!$C$14 -> 168816.09
A35: =(35-2)/100 -> 0.33 | B35: =Dashboard!$C$10*EXP(-Dashboard!$C$12*A35) -> 0.17818411 | C35: =Dashboard!$C$17*A35 -> 264 | D35: =Dashboard!$C$15*(1-EXP(-Dashboard!$C$16*A35)) -> 0.12168504 | E35: =1/(1+EXP(MIN(700,MAX(-700,(C35-Dashboard!$C$18)/Dashboard!$C$19)))) -> 0.94751589 | F35: =D35*E35 -> 0.11529851 | G35: =Dashboard!$C$9*B35*Dashboard!$C$11*(1-F35) -> 315279.5 | H35: =Dashboard!$C$20*A35^2 -> 871.2 | I35: =G35+H35 -> 316150.7 | J35: =Dashboard!$C$13*A35 -> 6600 | K35: =Dashboard!$C$14*A35 -> 9900 | L35: =Dashboard!$C$21-K35 -> 1490100 | M35: =L35-I35-J35 -> 1167349.3 | N35: =J35+K35 -> 16500 | O35: =Dashboard!$C$15*(Dashboard!$C$16*EXP(-Dashboard!$C$16*A35)*E35-(1-EXP(-Dashboard!$C$16*A35))*Dashboard!$C$17/Dashboard!$C$19*E35*(1-E35)) -> 0.31328865 | P35: =Dashboard!$C$9*B35*Dashboard!$C$11*(-Dashboard!$C$12*(1-F35)-O35)+2*Dashboard!$C$20*A35 -> -216713.95 | Q35: =-P35-Dashboard!$C$13-Dashboard!$C$14 -> 166713.95
A36: =(36-2)/100 -> 0.34 | B36: =Dashboard!$C$10*EXP(-Dashboard!$C$12*A36) -> 0.17756156 | C36: =Dashboard!$C$17*A36 -> 272 | D36: =Dashboard!$C$15*(1-EXP(-Dashboard!$C$16*A36)) -> 0.12506815 | E36: =1/(1+EXP(MIN(700,MAX(-700,(C36-Dashboard!$C$18)/Dashboard!$C$19)))) -> 0.94684886 | F36: =D36*E36 -> 0.11842063 | G36: =Dashboard!$C$9*B36*Dashboard!$C$11*(1-F36) -> 313069.22 | H36: =Dashboard!$C$20*A36^2 -> 924.8 | I36: =G36+H36 -> 313994.02 | J36: =Dashboard!$C$13*A36 -> 6800 | K36: =Dashboard!$C$14*A36 -> 10200 | L36: =Dashboard!$C$21-K36 -> 1489800 | M36: =L36-I36-J36 -> 1169006 | N36: =J36+K36 -> 17000 | O36: =Dashboard!$C$15*(Dashboard!$C$16*EXP(-Dashboard!$C$16*A36)*E36-(1-EXP(-Dashboard!$C$16*A36))*Dashboard!$C$17/Dashboard!$C$19*E36*(1-E36)) -> 0.31113697 | P36: =Dashboard!$C$9*B36*Dashboard!$C$11*(-Dashboard!$C$12*(1-F36)-O36)+2*Dashboard!$C$20*A36 -> -214626.16 | Q36: =-P36-Dashboard!$C$13-Dashboard!$C$14 -> 164626.16
A37: =(37-2)/100 -> 0.35 | B37: =Dashboard!$C$10*EXP(-Dashboard!$C$12*A37) -> 0.17694118 | C37: =Dashboard!$C$17*A37 -> 280 | D37: =Dashboard!$C$15*(1-EXP(-Dashboard!$C$16*A37)) -> 0.12843438 | E37: =1/(1+EXP(MIN(700,MAX(-700,(C37-Dashboard!$C$18)/Dashboard!$C$19)))) -> 0.94617384 | F37: =D37*E37 -> 0.12152125 | G37: =Dashboard!$C$9*B37*Dashboard!$C$11*(1-F37) -> 310878.13 | H37: =Dashboard!$C$20*A37^2 -> 980 | I37: =G37+H37 -> 311858.13 | J37: =Dashboard!$C$13*A37 -> 7000 | K37: =Dashboard!$C$14*A37 -> 10500 | L37: =Dashboard!$C$21-K37 -> 1489500 | M37: =L37-I37-J37 -> 1170641.9 | N37: =J37+K37 -> 17500 | O37: =Dashboard!$C$15*(Dashboard!$C$16*EXP(-Dashboard!$C$16*A37)*E37-(1-EXP(-Dashboard!$C$16*A37))*Dashboard!$C$17/Dashboard!$C$19*E37*(1-E37)) -> 0.30898754 | P37: =Dashboard!$C$9*B37*Dashboard!$C$11*(-Dashboard!$C$12*(1-F37)-O37)+2*Dashboard!$C$20*A37 -> -212552.59 | Q37: =-P37-Dashboard!$C$13-Dashboard!$C$14 -> 162552.59
A38: =(38-2)/100 -> 0.36 | B38: =Dashboard!$C$10*EXP(-Dashboard!$C$12*A38) -> 0.17632297 | C38: =Dashboard!$C$17*A38 -> 288 | D38: =Dashboard!$C$15*(1-EXP(-Dashboard!$C$16*A38)) -> 0.13178383 | E38: =1/(1+EXP(MIN(700,MAX(-700,(C38-Dashboard!$C$18)/Dashboard!$C$19)))) -> 0.94549073 | F38: =D38*E38 -> 0.12460039 | G38: =Dashboard!$C$9*B38*Dashboard!$C$11*(1-F38) -> 308706.12 | H38: =Dashboard!$C$20*A38^2 -> 1036.8 | I38: =G38+H38 -> 309742.92 | J38: =Dashboard!$C$13*A38 -> 7200 | K38: =Dashboard!$C$14*A38 -> 10800 | L38: =Dashboard!$C$21-K38 -> 1489200 | M38: =L38-I38-J38 -> 1172257.1 | N38: =J38+K38 -> 18000 | O38: =Dashboard!$C$15*(Dashboard!$C$16*EXP(-Dashboard!$C$16*A38)*E38-(1-EXP(-Dashboard!$C$16*A38))*Dashboard!$C$17/Dashboard!$C$19*E38*(1-E38)) -> 0.30684026 | P38: =Dashboard!$C$9*B38*Dashboard!$C$11*(-Dashboard!$C$12*(1-F38)-O38)+2*Dashboard!$C$20*A38 -> -210493.11 | Q38: =-P38-Dashboard!$C$13-Dashboard!$C$14 -> 160493.11
A39: =(39-2)/100 -> 0.37 | B39: =Dashboard!$C$10*EXP(-Dashboard!$C$12*A39) -> 0.17570692 | C39: =Dashboard!$C$17*A39 -> 296 | D39: =Dashboard!$C$15*(1-EXP(-Dashboard!$C$16*A39)) -> 0.13511657 | E39: =1/(1+EXP(MIN(700,MAX(-700,(C39-Dashboard!$C$18)/Dashboard!$C$19)))) -> 0.94479946 | F39: =D39*E39 -> 0.12765807 | G39: =Dashboard!$C$9*B39*Dashboard!$C$11*(1-F39) -> 306553.02 | H39: =Dashboard!$C$20*A39^2 -> 1095.2 | I39: =G39+H39 -> 307648.22 | J39: =Dashboard!$C$13*A39 -> 7400 | K39: =Dashboard!$C$14*A39 -> 11100 | L39: =Dashboard!$C$21-K39 -> 1488900 | M39: =L39-I39-J39 -> 1173851.8 | N39: =J39+K39 -> 18500 | O39: =Dashboard!$C$15*(Dashboard!$C$16*EXP(-Dashboard!$C$16*A39)*E39-(1-EXP(-Dashboard!$C$16*A39))*Dashboard!$C$17/Dashboard!$C$19*E39*(1-E39)) -> 0.30469503 | P39: =Dashboard!$C$9*B39*Dashboard!$C$11*(-Dashboard!$C$12*(1-F39)-O39)+2*Dashboard!$C$20*A39 -> -208447.61 | Q39: =-P39-Dashboard!$C$13-Dashboard!$C$14 -> 158447.61
A40: =(40-2)/100 -> 0.38 | B40: =Dashboard!$C$10*EXP(-Dashboard!$C$12*A40) -> 0.17509302 | C40: =Dashboard!$C$17*A40 -> 304 | D40: =Dashboard!$C$15*(1-EXP(-Dashboard!$C$16*A40)) -> 0.13843269 | E40: =1/(1+EXP(MIN(700,MAX(-700,(C40-Dashboard!$C$18)/Dashboard!$C$19)))) -> 0.94409994 | F40: =D40*E40 -> 0.1306943 | G40: =Dashboard!$C$9*B40*Dashboard!$C$11*(1-F40) -> 304418.72 | H40: =Dashboard!$C$20*A40^2 -> 1155.2 | I40: =G40+H40 -> 305573.92 | J40: =Dashboard!$C$13*A40 -> 7600 | K40: =Dashboard!$C$14*A40 -> 11400 | L40: =Dashboard!$C$21-K40 -> 1488600 | M40: =L40-I40-J40 -> 1175426.1 | N40: =J40+K40 -> 19000 | O40: =Dashboard!$C$15*(Dashboard!$C$16*EXP(-Dashboard!$C$16*A40)*E40-(1-EXP(-Dashboard!$C$16*A40))*Dashboard!$C$17/Dashboard!$C$19*E40*(1-E40)) -> 0.30255174 | P40: =Dashboard!$C$9*B40*Dashboard!$C$11*(-Dashboard!$C$12*(1-F40)-O40)+2*Dashboard!$C$20*A40 -> -206415.95 | Q40: =-P40-Dashboard!$C$13-Dashboard!$C$14 -> 156415.95
...

Sheet Examples
B2: Synthetic scenario presets — not estimates of the named sectors
B3: Blue columns are inputs; rows 20-26 are live per scenario. Transcribe a column into the Dashboard to explore it.
B5: parameter | C5: Summarization | D5: MCP DevOps | E5: Finance | F5: Drafting | G5: High-loss / smooth | H5: High-loss / steep
B6: lambda | C6: 25 | D6: 60 | E6: 15 | F6: 10 | G6: 40 | H6: 40
B7: q0 | C7: 0.3 | D7: 0.25 | E7: 0.15 | F7: 0.35 | G7: 0.2 | H7: 0.2
B8: L0 | C8: 80000 | D8: 400000 | E8: 1200000 | F8: 5000 | G8: 250000 | H8: 250000
B9: gamma | C9: 0.3 | D9: 0.45 | E9: 0.5 | F9: 0.3 | G9: 0.35 | H9: 0.35
B10: c | C10: 10000 | D10: 25000 | E10: 40000 | F10: 8000 | G10: 20000 | H10: 20000
B11: tau | C11: 25000 | D11: 20000 | E11: 45000 | F11: 12000 | G11: 30000 | H11: 30000
B12: h_max | C12: 0.6 | D12: 0.75 | E12: 0.85 | F12: 0.4 | G12: 0.8 | H12: 0.8
B13: kappa_d | C13: 0.4 | D13: 0.6 | E13: 0.7 | F13: 0.3 | G13: 0.5 | H13: 0.5
B14: v0 | C14: 1500 | D14: 400 | E14: 200 | F14: 600 | G14: 800 | H14: 800
B15: Ac | C15: 2500 | D15: 1500 | E15: 1000 | F15: 800 | G15: 2000 | H15: 2000
B16: s | C16: 450 | D16: 300 | E16: 250 | F16: 150 | G16: 600 | H16: 250
B17: D1 | C17: 15000 | D17: 5000 | E17: 3000 | F17: 20000 | G17: 8000 | H17: 8000
B18: B0 | C18: 600000 | D18: 2500000 | E18: 3000000 | F18: 150000 | G18: 1500000 | H18: 1500000
B20: R0 (baseline expected loss) | C20: =C6*C7*C8 -> 600000 | D20: =D6*D7*D8 -> 6000000 | E20: =E6*E7*E8 -> 2700000 | F20: =F6*F7*F8 -> 17500 | G20: =G6*G7*G8 -> 2000000 | H20: =H6*H7*H8 -> 2000000
B21: k = c + tau | C21: =C10+C11 -> 35000 | D21: =D10+D11 -> 45000 | E21: =E10+E11 -> 85000 | F21: =F10+F11 -> 20000 | G21: =G10+G11 -> 50000 | H21: =H10+H11 -> 50000
B22: q-only closed-form interior? | C22: =IF(C9*C20>C21,"Interior","Corner") -> Interior | D22: =IF(D9*D20>D21,"Interior","Corner") -> Interior | E22: =IF(E9*E20>E21,"Interior","Corner") -> Interior | F22: =IF(F9*F20>F21,"Interior","Corner") -> Corner | G22: =IF(G9*G20>G21,"Interior","Corner") -> Interior | H22: =IF(H9*H20>H21,"Interior","Corner") -> Interior
B23: z* closed form (q-only) | C23: =IF(AND(C9>0,C21>0,C9*C20>C21),LN(C9*C20/C21)/C9,0) -> 5.458696 | D23: =IF(AND(D9>0,D21>0,D9*D20>D21),LN(D9*D20/D21)/D9,0) -> 9.0985435 | E23: =IF(AND(E9>0,E21>0,E9*E20>E21),LN(E9*E20/E21)/E9,0) -> 5.5304172 | F23: =IF(AND(F9>0,F21>0,F9*F20>F21),LN(F9*F20/F21)/F9,0) -> 0 | G23: =IF(AND(G9>0,G21>0,G9*G20>G21),LN(G9*G20/G21)/G9,0) -> 7.5401638 | H23: =IF(AND(H9>0,H21>0,H9*H20>H21),LN(H9*H20/H21)/H9,0) -> 7.5401638
B24: all-in share at closed-form z* | C24: =IF(C20>0,C21*C23/C20,0) -> 0.31842393 | D24: =IF(D20>0,D21*D23/D20,0) -> 0.068239076 | E24: =IF(E20>0,E21*E23/E20,0) -> 0.17410573 | F24: =IF(F20>0,F21*F23/F20,0) -> 0 | G24: =IF(G20>0,G21*G23/G20,0) -> 0.18850409 | H24: =IF(H20>0,H21*H23/H20,0) -> 0.18850409
B25: welfare-optimal z (full model) | C25: =INDEX(ScenarioCurves!$A$2:$A$1002,MATCH(MAX(ScenarioCurves!B2:B1002),ScenarioCurves!B2:B1002,0)) -> 1.35 | D25: =INDEX(ScenarioCurves!$A$2:$A$1002,MATCH(MAX(ScenarioCurves!D2:D1002),ScenarioCurves!D2:D1002,0)) -> 6.93 | E25: =INDEX(ScenarioCurves!$A$2:$A$1002,MATCH(MAX(ScenarioCurves!F2:F1002),ScenarioCurves!F2:F1002,0)) -> 2.98 | F25: =INDEX(ScenarioCurves!$A$2:$A$1002,MATCH(MAX(ScenarioCurves!H2:H1002),ScenarioCurves!H2:H1002,0)) -> 0 | G25: =INDEX(ScenarioCurves!$A$2:$A$1002,MATCH(MAX(ScenarioCurves!J2:J1002),ScenarioCurves!J2:J1002,0)) -> 2.59 | H25: =INDEX(ScenarioCurves!$A$2:$A$1002,MATCH(MAX(ScenarioCurves!L2:L1002),ScenarioCurves!L2:L1002,0)) -> 2.02
B26: realized-risk min z (full model) | C26: =INDEX(ScenarioCurves!$A$2:$A$1002,MATCH(MIN(ScenarioCurves!C2:C1002),ScenarioCurves!C2:C1002,0)) -> 1.51 | D26: =INDEX(ScenarioCurves!$A$2:$A$1002,MATCH(MIN(ScenarioCurves!E2:E1002),ScenarioCurves!E2:E1002,0)) -> 7.84 | E26: =INDEX(ScenarioCurves!$A$2:$A$1002,MATCH(MIN(ScenarioCurves!G2:G1002),ScenarioCurves!G2:G1002,0)) -> 5.09 | F26: =INDEX(ScenarioCurves!$A$2:$A$1002,MATCH(MIN(ScenarioCurves!I2:I1002),ScenarioCurves!I2:I1002,0)) -> 0.17 | G26: =INDEX(ScenarioCurves!$A$2:$A$1002,MATCH(MIN(ScenarioCurves!K2:K1002),ScenarioCurves!K2:K1002,0)) -> 5.69 | H26: =INDEX(ScenarioCurves!$A$2:$A$1002,MATCH(MIN(ScenarioCurves!M2:M1002),ScenarioCurves!M2:M1002,0)) -> 5.78

Sheet ScenarioCurves
A1: Intensity x | B1: Summarization welfare | C1: Summarization risk | D1: MCP DevOps welfare | E1: MCP DevOps risk | F1: Finance welfare | G1: Finance risk | H1: Drafting welfare | I1: Drafting risk | J1: High-loss / smooth welfare | K1: High-loss / smooth risk | L1: High-loss / steep welfare | M1: High-loss / steep risk
A2: =(2-2)/100 -> 0 | B2: =Examples!$C$18-(Examples!$C$10+Examples!$C$11)*$A2-(Examples!$C$6*Examples!$C$7*Examples!$C$8*EXP(-Examples!$C$9*$A2)*(1-(Examples!$C$12*(1-EXP(-Examples!$C$13*$A2))/(1+EXP(MIN(700,MAX(-700,(Examples!$C$14*$A2-Examples!$C$15)/Examples!$C$16))))))+Examples!$C$17*$A2^2) -> 0 | C2: =(Examples!$C$6*Examples!$C$7*Examples!$C$8*EXP(-Examples!$C$9*$A2)*(1-(Examples!$C$12*(1-EXP(-Examples!$C$13*$A2))/(1+EXP(MIN(700,MAX(-700,(Examples!$C$14*$A2-Examples!$C$15)/Examples!$C$16))))))+Examples!$C$17*$A2^2) -> 600000 | D2: =Examples!$D$18-(Examples!$D$10+Examples!$D$11)*$A2-(Examples!$D$6*Examples!$D$7*Examples!$D$8*EXP(-Examples!$D$9*$A2)*(1-(Examples!$D$12*(1-EXP(-Examples!$D$13*$A2))/(1+EXP(MIN(700,MAX(-700,(Examples!$D$14*$A2-Examples!$D$15)/Examples!$D$16))))))+Examples!$D$17*$A2^2) -> -3500000 | E2: =(Examples!$D$6*Examples!$D$7*Examples!$D$8*EXP(-Examples!$D$9*$A2)*(1-(Examples!$D$12*(1-EXP(-Examples!$D$13*$A2))/(1+EXP(MIN(700,MAX(-700,(Examples!$D$14*$A2-Examples!$D$15)/Examples!$D$16))))))+Examples!$D$17*$A2^2) -> 6000000 | F2: =Examples!$E$18-(Examples!$E$10+Examples!$E$11)*$A2-(Examples!$E$6*Examples!$E$7*Examples!$E$8*EXP(-Examples!$E$9*$A2)*(1-(Examples!$E$12*(1-EXP(-Examples!$E$13*$A2))/(1+EXP(MIN(700,MAX(-700,(Examples!$E$14*$A2-Examples!$E$15)/Examples!$E$16))))))+Examples!$E$17*$A2^2) -> 300000 | G2: =(Examples!$E$6*Examples!$E$7*Examples!$E$8*EXP(-Examples!$E$9*$A2)*(1-(Examples!$E$12*(1-EXP(-Examples!$E$13*$A2))/(1+EXP(MIN(700,MAX(-700,(Examples!$E$14*$A2-Examples!$E$15)/Examples!$E$16))))))+Examples!$E$17*$A2^2) -> 2700000 | H2: =Examples!$F$18-(Examples!$F$10+Examples!$F$11)*$A2-(Examples!$F$6*Examples!$F$7*Examples!$F$8*EXP(-Examples!$F$9*$A2)*(1-(Examples!$F$12*(1-EXP(-Examples!$F$13*$A2))/(1+EXP(MIN(700,MAX(-700,(Examples!$F$14*$A2-Examples!$F$15)/Examples!$F$16))))))+Examples!$F$17*$A2^2) -> 132500 | I2: =(Examples!$F$6*Examples!$F$7*Examples!$F$8*EXP(-Examples!$F$9*$A2)*(1-(Examples!$F$12*(1-EXP(-Examples!$F$13*$A2))/(1+EXP(MIN(700,MAX(-700,(Examples!$F$14*$A2-Examples!$F$15)/Examples!$F$16))))))+Examples!$F$17*$A2^2) -> 17500 | J2: =Examples!$G$18-(Examples!$G$10+Examples!$G$11)*$A2-(Examples!$G$6*Examples!$G$7*Examples!$G$8*EXP(-Examples!$G$9*$A2)*(1-(Examples!$G$12*(1-EXP(-Examples!$G$13*$A2))/(1+EXP(MIN(700,MAX(-700,(Examples!$G$14*$A2-Examples!$G$15)/Examples!$G$16))))))+Examples!$G$17*$A2^2) -> -500000 | K2: =(Examples!$G$6*Examples!$G$7*Examples!$G$8*EXP(-Examples!$G$9*$A2)*(1-(Examples!$G$12*(1-EXP(-Examples!$G$13*$A2))/(1+EXP(MIN(700,MAX(-700,(Examples!$G$14*$A2-Examples!$G$15)/Examples!$G$16))))))+Examples!$G$17*$A2^2) -> 2000000 | L2: =Examples!$H$18-(Examples!$H$10+Examples!$H$11)*$A2-(Examples!$H$6*Examples!$H$7*Examples!$H$8*EXP(-Examples!$H$9*$A2)*(1-(Examples!$H$12*(1-EXP(-Examples!$H$13*$A2))/(1+EXP(MIN(700,MAX(-700,(Examples!$H$14*$A2-Examples!$H$15)/Examples!$H$16))))))+Examples!$H$17*$A2^2) -> -500000 | M2: =(Examples!$H$6*Examples!$H$7*Examples!$H$8*EXP(-Examples!$H$9*$A2)*(1-(Examples!$H$12*(1-EXP(-Examples!$H$13*$A2))/(1+EXP(MIN(700,MAX(-700,(Examples!$H$14*$A2-Examples!$H$15)/Examples!$H$16))))))+Examples!$H$17*$A2^2) -> 2000000
A3: =(3-2)/100 -> 0.01 | B3: =Examples!$C$18-(Examples!$C$10+Examples!$C$11)*$A3-(Examples!$C$6*Examples!$C$7*Examples!$C$8*EXP(-Examples!$C$9*$A3)*(1-(Examples!$C$12*(1-EXP(-Examples!$C$13*$A3))/(1+EXP(MIN(700,MAX(-700,(Examples!$C$14*$A3-Examples!$C$15)/Examples!$C$16))))))+Examples!$C$17*$A3^2) -> 2872.9175 | C3: =(Examples!$C$6*Examples!$C$7*Examples!$C$8*EXP(-Examples!$C$9*$A3)*(1-(Examples!$C$12*(1-EXP(-Examples!$C$13*$A3))/(1+EXP(MIN(700,MAX(-700,(Examples!$C$14*$A3-Examples!$C$15)/Examples!$C$16))))))+Examples!$C$17*$A3^2) -> 596777.08 | D3: =Examples!$D$18-(Examples!$D$10+Examples!$D$11)*$A3-(Examples!$D$6*Examples!$D$7*Examples!$D$8*EXP(-Examples!$D$9*$A3)*(1-(Examples!$D$12*(1-EXP(-Examples!$D$13*$A3))/(1+EXP(MIN(700,MAX(-700,(Examples!$D$14*$A3-Examples!$D$15)/Examples!$D$16))))))+Examples!$D$17*$A3^2) -> -3446894.6 | E3: =(Examples!$D$6*Examples!$D$7*Examples!$D$8*EXP(-Examples!$D$9*$A3)*(1-(Examples!$D$12*(1-EXP(-Examples!$D$13*$A3))/(1+EXP(MIN(700,MAX(-700,(Examples!$D$14*$A3-Examples!$D$15)/Examples!$D$16))))))+Examples!$D$17*$A3^2) -> 5946444.6 | F3: =Examples!$E$18-(Examples!$E$10+Examples!$E$11)*$A3-(Examples!$E$6*Examples!$E$7*Examples!$E$8*EXP(-Examples!$E$9*$A3)*(1-(Examples!$E$12*(1-EXP(-Examples!$E$13*$A3))/(1+EXP(MIN(700,MAX(-700,(Examples!$E$14*$A3-Examples!$E$15)/Examples!$E$16))))))+Examples!$E$17*$A3^2) -> 328256.3 | G3: =(Examples!$E$6*Examples!$E$7*Examples!$E$8*EXP(-Examples!$E$9*$A3)*(1-(Examples!$E$12*(1-EXP(-Examples!$E$13*$A3))/(1+EXP(MIN(700,MAX(-700,(Examples!$E$14*$A3-Examples!$E$15)/Examples!$E$16))))))+Examples!$E$17*$A3^2) -> 2670893.7 | H3: =Examples!$F$18-(Examples!$F$10+Examples!$F$11)*$A3-(Examples!$F$6*Examples!$F$7*Examples!$F$8*EXP(-Examples!$F$9*$A3)*(1-(Examples!$F$12*(1-EXP(-Examples!$F$13*$A3))/(1+EXP(MIN(700,MAX(-700,(Examples!$F$14*$A3-Examples!$F$15)/Examples!$F$16))))))+Examples!$F$17*$A3^2) -> 132371.22 | I3: =(Examples!$F$6*Examples!$F$7*Examples!$F$8*EXP(-Examples!$F$9*$A3)*(1-(Examples!$F$12*(1-EXP(-Examples!$F$13*$A3))/(1+EXP(MIN(700,MAX(-700,(Examples!$F$14*$A3-Examples!$F$15)/Examples!$F$16))))))+Examples!$F$17*$A3^2) -> 17428.777 | J3: =Examples!$G$18-(Examples!$G$10+Examples!$G$11)*$A3-(Examples!$G$6*Examples!$G$7*Examples!$G$8*EXP(-Examples!$G$9*$A3)*(1-(Examples!$G$12*(1-EXP(-Examples!$G$13*$A3))/(1+EXP(MIN(700,MAX(-700,(Examples!$G$14*$A3-Examples!$G$15)/Examples!$G$16))))))+Examples!$G$17*$A3^2) -> -485838.35 | K3: =(Examples!$G$6*Examples!$G$7*Examples!$G$8*EXP(-Examples!$G$9*$A3)*(1-(Examples!$G$12*(1-EXP(-Examples!$G$13*$A3))/(1+EXP(MIN(700,MAX(-700,(Examples!$G$14*$A3-Examples!$G$15)/Examples!$G$16))))))+Examples!$G$17*$A3^2) -> 1985338.3 | L3: =Examples!$H$18-(Examples!$H$10+Examples!$H$11)*$A3-(Examples!$H$6*Examples!$H$7*Examples!$H$8*EXP(-Examples!$H$9*$A3)*(1-(Examples!$H$12*(1-EXP(-Examples!$H$13*$A3))/(1+EXP(MIN(700,MAX(-700,(Examples!$H$14*$A3-Examples!$H$15)/Examples!$H$16))))))+Examples!$H$17*$A3^2) -> -485563.64 | M3: =(Examples!$H$6*Examples!$H$7*Examples!$H$8*EXP(-Examples!$H$9*$A3)*(1-(Examples!$H$12*(1-EXP(-Examples!$H$13*$A3))/(1+EXP(MIN(700,MAX(-700,(Examples!$H$14*$A3-Examples!$H$15)/Examples!$H$16))))))+Examples!$H$17*$A3^2) -> 1985063.6
A4: =(4-2)/100 -> 0.02 | B4: =Examples!$C$18-(Examples!$C$10+Examples!$C$11)*$A4-(Examples!$C$6*Examples!$C$7*Examples!$C$8*EXP(-Examples!$C$9*$A4)*(1-(Examples!$C$12*(1-EXP(-Examples!$C$13*$A4))/(1+EXP(MIN(700,MAX(-700,(Examples!$C$14*$A4-Examples!$C$15)/Examples!$C$16))))))+Examples!$C$17*$A4^2) -> 5722.8382 | C4: =(Examples!$C$6*Examples!$C$7*Examples!$C$8*EXP(-Examples!$C$9*$A4)*(1-(Examples!$C$12*(1-EXP(-Examples!$C$13*$A4))/(1+EXP(MIN(700,MAX(-700,(Examples!$C$14*$A4-Examples!$C$15)/Examples!$C$16))))))+Examples!$C$17*$A4^2) -> 593577.16 | D4: =Examples!$D$18-(Examples!$D$10+Examples!$D$11)*$A4-(Examples!$D$6*Examples!$D$7*Examples!$D$8*EXP(-Examples!$D$9*$A4)*(1-(Examples!$D$12*(1-EXP(-Examples!$D$13*$A4))/(1+EXP(MIN(700,MAX(-700,(Examples!$D$14*$A4-Examples!$D$15)/Examples!$D$16))))))+Examples!$D$17*$A4^2) -> -3394313.5 | E4: =(Examples!$D$6*Examples!$D$7*Examples!$D$8*EXP(-Examples!$D$9*$A4)*(1-(Examples!$D$12*(1-EXP(-Examples!$D$13*$A4))/(1+EXP(MIN(700,MAX(-700,(Examples!$D$14*$A4-Examples!$D$15)/Examples!$D$16))))))+Examples!$D$17*$A4^2) -> 5893413.5 | F4: =Examples!$E$18-(Examples!$E$10+Examples!$E$11)*$A4-(Examples!$E$6*Examples!$E$7*Examples!$E$8*EXP(-Examples!$E$9*$A4)*(1-(Examples!$E$12*(1-EXP(-Examples!$E$13*$A4))/(1+EXP(MIN(700,MAX(-700,(Examples!$E$14*$A4-Examples!$E$15)/Examples!$E$16))))))+Examples!$E$17*$A4^2) -> 356175.76 | G4: =(Examples!$E$6*Examples!$E$7*Examples!$E$8*EXP(-Examples!$E$9*$A4)*(1-(Examples!$E$12*(1-EXP(-Examples!$E$13*$A4))/(1+EXP(MIN(700,MAX(-700,(Examples!$E$14*$A4-Examples!$E$15)/Examples!$E$16))))))+Examples!$E$17*$A4^2) -> 2642124.2 | H4: =Examples!$F$18-(Examples!$F$10+Examples!$F$11)*$A4-(Examples!$F$6*Examples!$F$7*Examples!$F$8*EXP(-Examples!$F$9*$A4)*(1-(Examples!$F$12*(1-EXP(-Examples!$F$13*$A4))/(1+EXP(MIN(700,MAX(-700,(Examples!$F$14*$A4-Examples!$F$15)/Examples!$F$16))))))+Examples!$F$17*$A4^2) -> 132238.09 | I4: =(Examples!$F$6*Examples!$F$7*Examples!$F$8*EXP(-Examples!$F$9*$A4)*(1-(Examples!$F$12*(1-EXP(-Examples!$F$13*$A4))/(1+EXP(MIN(700,MAX(-700,(Examples!$F$14*$A4-Examples!$F$15)/Examples!$F$16))))))+Examples!$F$17*$A4^2) -> 17361.907 | J4: =Examples!$G$18-(Examples!$G$10+Examples!$G$11)*$A4-(Examples!$G$6*Examples!$G$7*Examples!$G$8*EXP(-Examples!$G$9*$A4)*(1-(Examples!$G$12*(1-EXP(-Examples!$G$13*$A4))/(1+EXP(MIN(700,MAX(-700,(Examples!$G$14*$A4-Examples!$G$15)/Examples!$G$16))))))+Examples!$G$17*$A4^2) -> -471801.62 | K4: =(Examples!$G$6*Examples!$G$7*Examples!$G$8*EXP(-Examples!$G$9*$A4)*(1-(Examples!$G$12*(1-EXP(-Examples!$G$13*$A4))/(1+EXP(MIN(700,MAX(-700,(Examples!$G$14*$A4-Examples!$G$15)/Examples!$G$16))))))+Examples!$G$17*$A4^2) -> 1970801.6 | L4: =Examples!$H$18-(Examples!$H$10+Examples!$H$11)*$A4-(Examples!$H$6*Examples!$H$7*Examples!$H$8*EXP(-Examples!$H$9*$A4)*(1-(Examples!$H$12*(1-EXP(-Examples!$H$13*$A4))/(1+EXP(MIN(700,MAX(-700,(Examples!$H$14*$A4-Examples!$H$15)/Examples!$H$16))))))+Examples!$H$17*$A4^2) -> -471248.52 | M4: =(Examples!$H$6*Examples!$H$7*Examples!$H$8*EXP(-Examples!$H$9*$A4)*(1-(Examples!$H$12*(1-EXP(-Examples!$H$13*$A4))/(1+EXP(MIN(700,MAX(-700,(Examples!$H$14*$A4-Examples!$H$15)/Examples!$H$16))))))+Examples!$H$17*$A4^2) -> 1970248.5
A5: =(5-2)/100 -> 0.03 | B5: =Examples!$C$18-(Examples!$C$10+Examples!$C$11)*$A5-(Examples!$C$6*Examples!$C$7*Examples!$C$8*EXP(-Examples!$C$9*$A5)*(1-(Examples!$C$12*(1-EXP(-Examples!$C$13*$A5))/(1+EXP(MIN(700,MAX(-700,(Examples!$C$14*$A5-Examples!$C$15)/Examples!$C$16))))))+Examples!$C$17*$A5^2) -> 8549.8767 | C5: =(Examples!$C$6*Examples!$C$7*Examples!$C$8*EXP(-Examples!$C$9*$A5)*(1-(Examples!$C$12*(1-EXP(-Examples!$C$13*$A5))/(1+EXP(MIN(700,MAX(-700,(Examples!$C$14*$A5-Examples!$C$15)/Examples!$C$16))))))+Examples!$C$17*$A5^2) -> 590400.12 | D5: =Examples!$D$18-(Examples!$D$10+Examples!$D$11)*$A5-(Examples!$D$6*Examples!$D$7*Examples!$D$8*EXP(-Examples!$D$9*$A5)*(1-(Examples!$D$12*(1-EXP(-Examples!$D$13*$A5))/(1+EXP(MIN(700,MAX(-700,(Examples!$D$14*$A5-Examples!$D$15)/Examples!$D$16))))))+Examples!$D$17*$A5^2) -> -3342251.4 | E5: =(Examples!$D$6*Examples!$D$7*Examples!$D$8*EXP(-Examples!$D$9*$A5)*(1-(Examples!$D$12*(1-EXP(-Examples!$D$13*$A5))/(1+EXP(MIN(700,MAX(-700,(Examples!$D$14*$A5-Examples!$D$15)/Examples!$D$16))))))+Examples!$D$17*$A5^2) -> 5840901.4 | F5: =Examples!$E$18-(Examples!$E$10+Examples!$E$11)*$A5-(Examples!$E$6*Examples!$E$7*Examples!$E$8*EXP(-Examples!$E$9*$A5)*(1-(Examples!$E$12*(1-EXP(-Examples!$E$13*$A5))/(1+EXP(MIN(700,MAX(-700,(Examples!$E$14*$A5-Examples!$E$15)/Examples!$E$16))))))+Examples!$E$17*$A5^2) -> 383762.31 | G5: =(Examples!$E$6*Examples!$E$7*Examples!$E$8*EXP(-Examples!$E$9*$A5)*(1-(Examples!$E$12*(1-EXP(-Examples!$E$13*$A5))/(1+EXP(MIN(700,MAX(-700,(Examples!$E$14*$A5-Examples!$E$15)/Examples!$E$16))))))+Examples!$E$17*$A5^2) -> 2613687.7 | H5: =Examples!$F$18-(Examples!$F$10+Examples!$F$11)*$A5-(Examples!$F$6*Examples!$F$7*Examples!$F$8*EXP(-Examples!$F$9*$A5)*(1-(Examples!$F$12*(1-EXP(-Examples!$F$13*$A5))/(1+EXP(MIN(700,MAX(-700,(Examples!$F$14*$A5-Examples!$F$15)/Examples!$F$16))))))+Examples!$F$17*$A5^2) -> 132100.61 | I5: =(Examples!$F$6*Examples!$F$7*Examples!$F$8*EXP(-Examples!$F$9*$A5)*(1-(Examples!$F$12*(1-EXP(-Examples!$F$13*$A5))/(1+EXP(MIN(700,MAX(-700,(Examples!$F$14*$A5-Examples!$F$15)/Examples!$F$16))))))+Examples!$F$17*$A5^2) -> 17299.388 | J5: =Examples!$G$18-(Examples!$G$10+Examples!$G$11)*$A5-(Examples!$G$6*Examples!$G$7*Examples!$G$8*EXP(-Examples!$G$9*$A5)*(1-(Examples!$G$12*(1-EXP(-Examples!$G$13*$A5))/(1+EXP(MIN(700,MAX(-700,(Examples!$G$14*$A5-Examples!$G$15)/Examples!$G$16))))))+Examples!$G$17*$A5^2) -> -457888.87 | K5: =(Examples!$G$6*Examples!$G$7*Examples!$G$8*EXP(-Examples!$G$9*$A5)*(1-(Examples!$G$12*(1-EXP(-Examples!$G$13*$A5))/(1+EXP(MIN(700,MAX(-700,(Examples!$G$14*$A5-Examples!$G$15)/Examples!$G$16))))))+Examples!$G$17*$A5^2) -> 1956388.9 | L5: =Examples!$H$18-(Examples!$H$10+Examples!$H$11)*$A5-(Examples!$H$6*Examples!$H$7*Examples!$H$8*EXP(-Examples!$H$9*$A5)*(1-(Examples!$H$12*(1-EXP(-Examples!$H$13*$A5))/(1+EXP(MIN(700,MAX(-700,(Examples!$H$14*$A5-Examples!$H$15)/Examples!$H$16))))))+Examples!$H$17*$A5^2) -> -457053.68 | M5: =(Examples!$H$6*Examples!$H$7*Examples!$H$8*EXP(-Examples!$H$9*$A5)*(1-(Examples!$H$12*(1-EXP(-Examples!$H$13*$A5))/(1+EXP(MIN(700,MAX(-700,(Examples!$H$14*$A5-Examples!$H$15)/Examples!$H$16))))))+Examples!$H$17*$A5^2) -> 1955553.7
